#VRML_SIM R2023b utf8

EXTERNPROTO "https://raw.githubusercontent.com/cyberbotics/webots/R2023b/projects/objects/backgrounds/protos/TexturedBackground.proto"
EXTERNPROTO "https://raw.githubusercontent.com/cyberbotics/webots/R2023b/projects/objects/backgrounds/protos/TexturedBackgroundLight.proto"
EXTERNPROTO "https://raw.githubusercontent.com/cyberbotics/webots/R2023b/projects/objects/floors/protos/RectangleArena.proto"
EXTERNPROTO "https://raw.githubusercontent.com/cyberbotics/webots/R2023b/projects/appearances/protos/Parquetry.proto"

WorldInfo {
}
Viewpoint {
  orientation 0.3043849708914303 0.12996289819361417 -0.9436415816339059 2.999692164461638
  position 1.2972868764953114 -0.021374343280920742 0.8547409937205278
}
TexturedBackground {
}
RectangleArena {
  floorAppearance Parquetry {
    type "light strip"
  }
  wallThickness 0.005
  wallHeight 0.06
}
TexturedBackgroundLight {
}
Robot {
  translation 0.052931 -0.000875199 0.00434942
  rotation 0.12524317265100282 0.4180870238235861 0.8997318423923026 0.0002368707825278184
  children [
    DEF Body Pose {
      translation 0 0 0.01
      children [
        DEF LIDAR_GROUP Group {
          children [
            DistanceSensor {
              translation 0.121 0.089 0.016
              children [
                Shape {
                  appearance PBRAppearance {
                    baseColor 0 0 0
                    roughness 1
                    metalness 0
                  }
                  geometry Box {
                    size 0.002 0.02 0.018
                  }
                }
              ]
              name "lidar(4)"
              lookupTable [
                0 0 0
                0.255 255 0
              ]
              type "laser"
              aperture 0
            }
            DistanceSensor {
              translation 0.121 0.043 0.016
              children [
                Shape {
                  appearance PBRAppearance {
                    baseColor 0 0 0
                    roughness 1
                    metalness 0
                  }
                  geometry Box {
                    size 0.002 0.02 0.018
                  }
                }
              ]
              name "lidar(5)"
              lookupTable [
                0 0 0
                0.255 255 0
              ]
              type "laser"
              aperture 0
            }
            DistanceSensor {
              translation 0.121 0 0.016
              children [
                Shape {
                  appearance PBRAppearance {
                    baseColor 0 0 0
                    roughness 1
                    metalness 0
                  }
                  geometry Box {
                    size 0.002 0.02 0.018
                  }
                }
              ]
              name "lidar(6)"
              lookupTable [
                0 0 0
                0.255 255 0
              ]
              type "laser"
              aperture 0
            }
            DistanceSensor {
              translation 0.121 -0.047 0.016
              children [
                Shape {
                  appearance PBRAppearance {
                    baseColor 0 0 0
                    roughness 1
                    metalness 0
                  }
                  geometry Box {
                    size 0.002 0.02 0.018
                  }
                }
              ]
              name "lidar(7)"
              lookupTable [
                0 0 0
                0.255 255 0
              ]
              type "laser"
              aperture 0
            }
            DistanceSensor {
              translation 0.121 -0.091 0.016
              children [
                Shape {
                  appearance PBRAppearance {
                    baseColor 0 0 0
                    roughness 1
                    metalness 0
                  }
                  geometry Box {
                    size 0.002 0.02 0.018
                  }
                }
              ]
              name "lidar(8)"
              lookupTable [
                0 0 0
                0.255 255 0
              ]
              type "laser"
              aperture 0
            }
            DistanceSensor {
              translation 0.086 -0.116 0.016
              rotation 0 0 1 -1.5707953071795862
              children [
                Shape {
                  appearance PBRAppearance {
                    baseColor 0 0 0
                    roughness 1
                    metalness 0
                  }
                  geometry Box {
                    size 0.002 0.02 0.018
                  }
                }
              ]
              name "lidar(9)"
              lookupTable [
                0 0 0
                0.255 255 0
              ]
              type "laser"
              aperture 0
              gaussianWidth 0.1
            }
            DistanceSensor {
              translation 0.006 -0.116 0.016
              rotation 0 0 1 -1.5707953071795862
              children [
                Shape {
                  appearance PBRAppearance {
                    baseColor 0 0 0
                    roughness 1
                    metalness 0
                  }
                  geometry Box {
                    size 0.002 0.02 0.018
                  }
                }
              ]
              name "lidar(10)"
              lookupTable [
                0 0 0
                0.255 255 0
              ]
              type "laser"
              aperture 0
              gaussianWidth 0.1
            }
            DistanceSensor {
              translation -0.074 -0.116 0.016
              rotation 0 0 1 -1.5707953071795862
              children [
                Shape {
                  appearance PBRAppearance {
                    baseColor 0 0 0
                    roughness 1
                    metalness 0
                  }
                  geometry Box {
                    size 0.002 0.02 0.018
                  }
                }
              ]
              name "lidar(11)"
              lookupTable [
                0 0 0
                0.255 255 0
              ]
              type "laser"
              aperture 0
              gaussianWidth 0.1
            }
            DistanceSensor {
              translation 0.114 0 0.005
              rotation 0.577349935856137 0.5773509358560258 -0.577349935856137 2.09439
              children [
                Shape {
                  appearance PBRAppearance {
                    baseColor 0 0 0
                    roughness 1
                    metalness 0
                  }
                  geometry Box {
                    size 0.002 0.02 0.018
                  }
                }
              ]
              name "emergencyLidar"
              lookupTable [
                0 0 0
                0.255 255 0
              ]
              type "laser"
              aperture 0
              gaussianWidth 0.1
            }
            DistanceSensor {
              translation -0.108 -0.001 0.016
              rotation 0 0 1 3.14159
              children [
                Shape {
                  appearance PBRAppearance {
                    baseColor 0 0 0
                    roughness 1
                    metalness 0
                  }
                  geometry Box {
                    size 0.002 0.02 0.018
                  }
                }
              ]
              name "lidar"
              lookupTable [
                0 0 0
                0.255 255 0
              ]
              type "laser"
              aperture 0
              gaussianWidth 0.1
            }
            DistanceSensor {
              translation 0.007 0.114 0.016
              rotation 0 0 -1 -1.5707953071795862
              children [
                Shape {
                  appearance PBRAppearance {
                    baseColor 0 0 0
                    roughness 1
                    metalness 0
                  }
                  geometry Box {
                    size 0.002 0.02 0.018
                  }
                }
              ]
              name "lidar(2)"
              lookupTable [
                0 0 0
                0.255 255 0
              ]
              type "laser"
              aperture 0
              gaussianWidth 0.1
            }
            DistanceSensor {
              translation -0.073 0.114 0.016
              rotation 0 0 -1 -1.5707953071795862
              children [
                Shape {
                  appearance PBRAppearance {
                    baseColor 0 0 0
                    roughness 1
                    metalness 0
                  }
                  geometry Box {
                    size 0.002 0.02 0.018
                  }
                }
              ]
              name "lidar(1)"
              lookupTable [
                0 0 0
                0.255 255 0
              ]
              type "laser"
              aperture 0
              gaussianWidth 0.1
            }
            DistanceSensor {
              translation 0.087 0.114 0.016
              rotation 0 0 -1 -1.5707953071795862
              children [
                Shape {
                  appearance PBRAppearance {
                    baseColor 0 0 0
                    roughness 1
                    metalness 0
                  }
                  geometry Box {
                    size 0.002 0.02 0.018
                  }
                }
              ]
              name "lidar(3)"
              lookupTable [
                0 0 0
                0.255 255 0
              ]
              type "laser"
              aperture 0
              gaussianWidth 0.1
            }
          ]
        }
        DEF LEDS_GROUP Group {
          children [
            LED {
              translation -0.12 -0.030001 0.0199988
              rotation 6.247492484361515e-07 0.707106281186034 -0.7071072811864317 3.1415853071795863
              children [
                SpotLight {
                  attenuation 0 0 1
                  beamWidth 0
                  color 0 0 0
                  cutOffAngle 0.1
                  direction 0 0 0
                  intensity 0.1
                  on FALSE
                  radius 1
                }
              ]
            }
            LED {
              translation -0.12 -0.06 0.0199988
              rotation 6.247492484361515e-07 0.707106281186034 -0.7071072811864317 3.1415853071795863
              children [
                SpotLight {
                  attenuation 0 0 1
                  beamWidth 0
                  color 0 0 0
                  cutOffAngle 0.1
                  direction 0 0 0
                  intensity 0.1
                  on FALSE
                  radius 1
                }
              ]
              name "led(1)"
            }
            LED {
              translation -0.12 -0.09 0.0199988
              rotation 6.247492484361515e-07 0.707106281186034 -0.7071072811864317 3.1415853071795863
              children [
                SpotLight {
                  attenuation 0 0 1
                  beamWidth 0
                  color 0 0 0
                  cutOffAngle 0.1
                  direction 0 0 0
                  intensity 0.1
                  on FALSE
                  radius 1
                }
              ]
              name "led(2)"
            }
            LED {
              translation -0.09 -0.125 0.02
              rotation 6.247492484361515e-07 0.707106281186034 -0.7071072811864317 3.1415853071795863
              children [
                SpotLight {
                  attenuation 0 0 1
                  beamWidth 0
                  color 0 0 0
                  cutOffAngle 0.1
                  direction 0 0 0
                  intensity 0.1
                  on FALSE
                  radius 1
                }
              ]
              name "led(3)"
            }
            LED {
              translation -0.065 -0.128 0.0200002
              rotation 6.247492484361515e-07 0.707106281186034 -0.7071072811864317 3.1415853071795863
              children [
                SpotLight {
                  attenuation 0 0 1
                  beamWidth 0
                  color 0 0 0
                  cutOffAngle 0.1
                  direction 0 0 0
                  intensity 0.1
                  on FALSE
                  radius 1
                }
              ]
              name "led(4)"
            }
            LED {
              translation -0.035 -0.128 0.0200004
              rotation 6.247492484361515e-07 0.707106281186034 -0.7071072811864317 3.1415853071795863
              children [
                SpotLight {
                  attenuation 0 0 1
                  beamWidth 0
                  color 0 0 0
                  cutOffAngle 0.1
                  direction 0 0 0
                  intensity 0.1
                  on FALSE
                  radius 1
                }
              ]
              name "led(5)"
            }
            LED {
              translation -0.005 -0.128 0.0200006
              rotation 6.247492484361515e-07 0.707106281186034 -0.7071072811864317 3.1415853071795863
              children [
                SpotLight {
                  attenuation 0 0 1
                  beamWidth 0
                  color 0 0 0
                  cutOffAngle 0.1
                  direction 0 0 0
                  intensity 0.1
                  on FALSE
                  radius 1
                }
              ]
              name "led(6)"
            }
            LED {
              translation 0.025 -0.128 0.0200008
              rotation 6.247492484361515e-07 0.707106281186034 -0.7071072811864317 3.1415853071795863
              children [
                SpotLight {
                  attenuation 0 0 1
                  beamWidth 0
                  color 0 0 0
                  cutOffAngle 0.1
                  direction 0 0 0
                  intensity 0.1
                  on FALSE
                  radius 1
                }
              ]
              name "led(7)"
            }
            LED {
              translation 0.055 -0.128 0.020001
              rotation 6.247492484361515e-07 0.707106281186034 -0.7071072811864317 3.1415853071795863
              children [
                SpotLight {
                  attenuation 0 0 1
                  beamWidth 0
                  color 0 0 0
                  cutOffAngle 0.1
                  direction 0 0 0
                  intensity 0.1
                  on FALSE
                  radius 1
                }
              ]
              name "led(8)"
            }
            LED {
              translation 0.085 -0.128 0.0200012
              rotation 6.247492484361515e-07 0.707106281186034 -0.7071072811864317 3.1415853071795863
              children [
                SpotLight {
                  attenuation 0 0 1
                  beamWidth 0
                  color 0 0 0
                  cutOffAngle 0.1
                  direction 0 0 0
                  intensity 0.1
                  on FALSE
                  radius 1
                }
              ]
              name "led(9)"
            }
            LED {
              translation 0.132 -0.108 0.0200016
              rotation 6.247492484361515e-07 0.707106281186034 -0.7071072811864317 3.1415853071795863
              children [
                SpotLight {
                  attenuation 0 0 1
                  beamWidth 0
                  color 0 0 0
                  cutOffAngle 0.1
                  direction 0 0 0
                  intensity 0.1
                  on FALSE
                  radius 1
                }
              ]
              name "led(10)"
            }
            LED {
              translation 0.132 -0.078 0.0200016
              rotation 6.247492484361515e-07 0.707106281186034 -0.7071072811864317 3.1415853071795863
              children [
                SpotLight {
                  attenuation 0 0 1
                  beamWidth 0
                  color 0 0 0
                  cutOffAngle 0.1
                  direction 0 0 0
                  intensity 0.1
                  on FALSE
                  radius 1
                }
              ]
              name "led(11)"
            }
            LED {
              translation 0.132 -0.048 0.0200016
              rotation 6.247492484361515e-07 0.707106281186034 -0.7071072811864317 3.1415853071795863
              children [
                SpotLight {
                  attenuation 0 0 1
                  beamWidth 0
                  color 0 0 0
                  cutOffAngle 0.1
                  direction 0 0 0
                  intensity 0.1
                  on FALSE
                  radius 1
                }
              ]
              name "led(12)"
            }
            LED {
              translation 0.132 -0.018 0.0200016
              rotation 6.247492484361515e-07 0.707106281186034 -0.7071072811864317 3.1415853071795863
              children [
                SpotLight {
                  attenuation 0 0 1
                  beamWidth 0
                  color 0 0 0
                  cutOffAngle 0.1
                  direction 0 0 0
                  intensity 0.1
                  on FALSE
                  radius 1
                }
              ]
              name "led(13)"
            }
            LED {
              translation 0.132 0.012 0.0200016
              rotation 6.247492484361515e-07 0.707106281186034 -0.7071072811864317 3.1415853071795863
              children [
                SpotLight {
                  attenuation 0 0 1
                  beamWidth 0
                  color 0 0 0
                  cutOffAngle 0.1
                  direction 0 0 0
                  intensity 0.1
                  on FALSE
                  radius 1
                }
              ]
              name "led(14)"
            }
            LED {
              translation 0.132 0.042 0.0200016
              rotation 6.247492484361515e-07 0.707106281186034 -0.7071072811864317 3.1415853071795863
              children [
                SpotLight {
                  attenuation 0 0 1
                  beamWidth 0
                  color 0 0 0
                  cutOffAngle 0.1
                  direction 0 0 0
                  intensity 0.1
                  on FALSE
                  radius 1
                }
              ]
              name "led(15)"
            }
            LED {
              translation 0.132 0.072 0.0200016
              rotation 6.247492484361515e-07 0.707106281186034 -0.7071072811864317 3.1415853071795863
              children [
                SpotLight {
                  attenuation 0 0 1
                  beamWidth 0
                  color 0 0 0
                  cutOffAngle 0.1
                  direction 0 0 0
                  intensity 0.1
                  on FALSE
                  radius 1
                }
              ]
              name "led(16)"
            }
            LED {
              translation 0.122 0.123 0.0200015
              rotation 6.247492484361515e-07 0.707106281186034 -0.7071072811864317 3.1415853071795863
              children [
                SpotLight {
                  attenuation 0 0 1
                  beamWidth 0
                  color 0 0 0
                  cutOffAngle 0.1
                  direction 0 0 0
                  intensity 0.1
                  on FALSE
                  radius 1
                }
              ]
              name "led(17)"
            }
            LED {
              translation 0.085 0.123 0.0200015
              rotation 6.247492484361515e-07 0.707106281186034 -0.7071072811864317 3.1415853071795863
              children [
                SpotLight {
                  attenuation 0 0 1
                  beamWidth 0
                  color 0 0 0
                  cutOffAngle 0.1
                  direction 0 0 0
                  intensity 0.1
                  on FALSE
                  radius 1
                }
              ]
              name "led(18)"
            }
            LED {
              translation 0.055 0.123 0.0200015
              rotation 6.247492484361515e-07 0.707106281186034 -0.7071072811864317 3.1415853071795863
              children [
                SpotLight {
                  attenuation 0 0 1
                  beamWidth 0
                  color 0 0 0
                  cutOffAngle 0.1
                  direction 0 0 0
                  intensity 0.1
                  on FALSE
                  radius 1
                }
              ]
              name "led(19)"
            }
            LED {
              translation 0.025 0.123 0.0200015
              rotation 6.247492484361515e-07 0.707106281186034 -0.7071072811864317 3.1415853071795863
              children [
                SpotLight {
                  attenuation 0 0 1
                  beamWidth 0
                  color 0 0 0
                  cutOffAngle 0.1
                  direction 0 0 0
                  intensity 0.1
                  on FALSE
                  radius 1
                }
              ]
              name "led(20)"
            }
            LED {
              translation -0.005 0.123 0.0200015
              rotation 6.247492484361515e-07 0.707106281186034 -0.7071072811864317 3.1415853071795863
              children [
                SpotLight {
                  attenuation 0 0 1
                  beamWidth 0
                  color 0 0 0
                  cutOffAngle 0.1
                  direction 0 0 0
                  intensity 0.1
                  on FALSE
                  radius 1
                }
              ]
              name "led(21)"
            }
            LED {
              translation -0.035 0.123 0.0200015
              rotation 6.247492484361515e-07 0.707106281186034 -0.7071072811864317 3.1415853071795863
              children [
                SpotLight {
                  attenuation 0 0 1
                  beamWidth 0
                  color 0 0 0
                  cutOffAngle 0.1
                  direction 0 0 0
                  intensity 0.1
                  on FALSE
                  radius 1
                }
              ]
              name "led(22)"
            }
            LED {
              translation -0.065 0.123 0.0200015
              rotation 6.247492484361515e-07 0.707106281186034 -0.7071072811864317 3.1415853071795863
              children [
                SpotLight {
                  attenuation 0 0 1
                  beamWidth 0
                  color 0 0 0
                  cutOffAngle 0.1
                  direction 0 0 0
                  intensity 0.1
                  on FALSE
                  radius 1
                }
              ]
              name "led(23)"
            }
            LED {
              translation -0.11 0.103 0.0200012
              rotation 6.247492484361515e-07 0.707106281186034 -0.7071072811864317 3.1415853071795863
              children [
                SpotLight {
                  attenuation 0 0 1
                  beamWidth 0
                  color 0 0 0
                  cutOffAngle 0.1
                  direction 0 0 0
                  intensity 0.1
                  on FALSE
                  radius 1
                }
              ]
              name "led(24)"
            }
            LED {
              translation -0.12 0.062 0.0200011
              rotation 6.247492484361515e-07 0.707106281186034 -0.7071072811864317 3.1415853071795863
              children [
                SpotLight {
                  attenuation 0 0 1
                  beamWidth 0
                  color 0 0 0
                  cutOffAngle 0.1
                  direction 0 0 0
                  intensity 0.1
                  on FALSE
                  radius 1
                }
              ]
              name "led(25)"
            }
          ]
        }
        DEF wheel_back BallJoint {
          jointParameters BallJointParameters {
            position -0.007694443371419334
            anchor -0.09 0 -0.005
          }
          jointParameters2 JointParameters {
            position -0.010956741404780394
          }
          jointParameters3 JointParameters {
            position 114.91687618188165
            axis 0 1 0
          }
          endPoint Solid {
            translation -0.0899950424036611 -1.909148276062118e-08 -0.004996905247157509
            rotation 0.001334395238145758 0.9999678702500394 -0.007904293576848747 1.8195944006811626
            children [
              DEF UNIVERSAL_WHEEL Shape {
                appearance PBRAppearance {
                  baseColor 0 0 0
                  roughness 1
                  metalness 0
                }
                geometry Sphere {
                  radius 0.01
                }
              }
            ]
            name "solid(3)"
            boundingObject USE UNIVERSAL_WHEEL
            physics Physics {
            }
          }
        }
        DEF wheel_front BallJoint {
          jointParameters BallJointParameters {
            position -0.00818924514340013
            anchor 0.1 0 -0.005
          }
          jointParameters2 JointParameters {
            position -0.05984629701675737
          }
          jointParameters3 JointParameters {
            position 116.89086666360889
            axis 0 1 0
          }
          endPoint Solid {
            translation 0.10000511434006454 5.173364905072947e-08 -0.004996776694449093
            rotation 0.01509777151343249 0.9996122914521421 -0.023394958284335778 3.793354863937479
            children [
              DEF UNIVERSAL_WHEEL Shape {
                appearance PBRAppearance {
                  baseColor 0 0 0
                  roughness 1
                  metalness 0
                }
                geometry Sphere {
                  radius 0.01
                }
              }
            ]
            name "solid(2)"
            boundingObject USE UNIVERSAL_WHEEL
            physics Physics {
            }
          }
        }
        Camera {
          translation 0.0607 -0.001 0.1663
          rotation 0 1 0 -0.620795307179586
          children [
            Pose {
              rotation 0 1 0 1.5708
              children [
                Shape {
                  appearance PBRAppearance {
                    roughness 0.1
                    metalness 0.9
                  }
                  geometry Cylinder {
                    height 0.01
                    radius 0.0073
                  }
                }
              ]
            }
          ]
          fieldOfView 2.04
          width 3296
          height 2512
          far 1000
          lens Lens {
          }
        }
        Solid {
          translation 0.1036 -0.001 0.1125
          rotation 0 1 0 0.95
          children [
            Shape {
              appearance PBRAppearance {
                roughness 0.2
                metalness 0.9
              }
              geometry Box {
                size 0.115 0.166 0.002
              }
              castShadows FALSE
              isPickable FALSE
            }
            Display {
            }
          ]
          name "Screen"
        }
        Speaker {
          translation 0 0 0.21
        }
        DEF wheel_right HingeJoint {
          jointParameters HingeJointParameters {
            position 128.78734066256337
            axis 0 1 0
            anchor -9.092519999999895e-07 -0.07999998763551178 0.010019798720924688
          }
          device [
            RotationalMotor {
              name "motor_right"
            }
          ]
          endPoint Solid {
            translation -9.126964386813957e-07 -0.08000001165951812 0.010019990504118023
            rotation 0.0063458119483419 0.7070908019955281 -0.7070942853707963 3.1288871679857304
            children [
              DEF WHEEL Shape {
                appearance PBRAppearance {
                  baseColor 0 0 0
                  roughness 1
                  metalness 0
                }
                geometry Cylinder {
                  height 0.01
                  radius 0.025
                }
              }
            ]
            boundingObject USE WHEEL
            physics DEF WHEEL_PhYSICS Physics {
            }
          }
        }
        DEF wheel_left HingeJoint {
          jointParameters HingeJointParameters {
            position 128.78734543662506
            axis 0 1 0
            anchor 7.207369999999995e-07 0.0799999876424674 0.010015098711698348
          }
          device [
            RotationalMotor {
              name "motor_left"
            }
          ]
          endPoint Solid {
            translation 7.173203984319008e-07 0.0800000114674744 0.010015288995543327
            rotation 0.006343982331038882 0.7070916252406573 -0.7070934785463017 3.1288902601387534
            children [
              USE WHEEL
            ]
            name "solid(1)"
            boundingObject USE WHEEL
            physics USE WHEEL_PhYSICS
          }
        }
        DEF Carcasa Shape {
          appearance PBRAppearance {
            roughness 1
            metalness 0
          }
          geometry Mesh {
            url [
              "../resources/meshes/EBO_Carcasa.stl"
            ]
          }
        }
        DEF Base Shape {
          appearance PBRAppearance {
            roughness 1
            metalness 0
          }
          geometry Mesh {
            url [
              "../resources/meshes/EBO_Base.stl"
            ]
          }
        }
      ]
    }
  ]
  name "EBO"
  model "EBOv2"
  boundingObject Pose {
    translation 0 0 0.01
    children [
      Mesh {
        url [
          "../resources/meshes/EBO_Collision.stl"
        ]
      }
    ]
  }
  physics Physics {
    density -1
    mass 2.4
  }
  controller "<extern>"
}
