#VRML_SIM R2023b utf8

EXTERNPROTO "https://raw.githubusercontent.com/cyberbotics/webots/R2023b/projects/objects/backgrounds/protos/TexturedBackground.proto"
EXTERNPROTO "https://raw.githubusercontent.com/cyberbotics/webots/R2023b/projects/objects/backgrounds/protos/TexturedBackgroundLight.proto"
EXTERNPROTO "https://raw.githubusercontent.com/cyberbotics/webots/R2023b/projects/objects/floors/protos/RectangleArena.proto"
EXTERNPROTO "https://raw.githubusercontent.com/cyberbotics/webots/R2023b/projects/appearances/protos/Parquetry.proto"

WorldInfo {
}
Viewpoint {
  orientation -0.38725348209309524 -0.08665550171287088 -0.9178919133697951 2.1500644993688973
  position 0.3866095928594556 0.5400755674405605 -0.4145151168430245
}
TexturedBackground {
}
RectangleArena {
  floorSize 2 2
  floorAppearance Parquetry {
    type "light strip"
  }
  wallThickness 0.005
  wallHeight 0.06
}
TexturedBackgroundLight {
}
Robot {
  translation 0.052930992889832336 -0.0008751990665366972 0.004338786588497984
  rotation 0.12536208990817116 0.41683988419996704 0.900293761698932 0.000236722313056881
  children [
    DEF Body Pose {
      translation 0 0 0.01
      children [
        DEF LIDAR_GROUP Group {
          children [
            DistanceSensor {
              translation 0.121 0.089 0.016
              children [
                Shape {
                  appearance PBRAppearance {
                    baseColor 0 0 0
                    roughness 1
                    metalness 0
                  }
                  geometry Box {
                    size 0.002 0.02 0.018
                  }
                }
              ]
              name "lidar(4)"
              lookupTable [
                0 0 0
                0.255 255 0
              ]
              type "laser"
              aperture 0
            }
            DistanceSensor {
              translation 0.121 0.043 0.016
              children [
                Shape {
                  appearance PBRAppearance {
                    baseColor 0 0 0
                    roughness 1
                    metalness 0
                  }
                  geometry Box {
                    size 0.002 0.02 0.018
                  }
                }
              ]
              name "lidar(5)"
              lookupTable [
                0 0 0
                0.255 255 0
              ]
              type "laser"
              aperture 0
            }
            DistanceSensor {
              translation 0.121 0 0.016
              children [
                Shape {
                  appearance PBRAppearance {
                    baseColor 0 0 0
                    roughness 1
                    metalness 0
                  }
                  geometry Box {
                    size 0.002 0.02 0.018
                  }
                }
              ]
              name "lidar(6)"
              lookupTable [
                0 0 0
                0.255 255 0
              ]
              type "laser"
              aperture 0
            }
            DistanceSensor {
              translation 0.121 -0.047 0.016
              children [
                Shape {
                  appearance PBRAppearance {
                    baseColor 0 0 0
                    roughness 1
                    metalness 0
                  }
                  geometry Box {
                    size 0.002 0.02 0.018
                  }
                }
              ]
              name "lidar(7)"
              lookupTable [
                0 0 0
                0.255 255 0
              ]
              type "laser"
              aperture 0
            }
            DistanceSensor {
              translation 0.121 -0.091 0.016
              children [
                Shape {
                  appearance PBRAppearance {
                    baseColor 0 0 0
                    roughness 1
                    metalness 0
                  }
                  geometry Box {
                    size 0.002 0.02 0.018
                  }
                }
              ]
              name "lidar(8)"
              lookupTable [
                0 0 0
                0.255 255 0
              ]
              type "laser"
              aperture 0
            }
            DistanceSensor {
              translation 0.086 -0.116 0.016
              rotation 0 0 1 -1.5707953071795862
              children [
                Shape {
                  appearance PBRAppearance {
                    baseColor 0 0 0
                    roughness 1
                    metalness 0
                  }
                  geometry Box {
                    size 0.002 0.02 0.018
                  }
                }
              ]
              name "lidar(9)"
              lookupTable [
                0 0 0
                0.255 255 0
              ]
              type "laser"
              aperture 0
              gaussianWidth 0.1
            }
            DistanceSensor {
              translation 0.006 -0.116 0.016
              rotation 0 0 1 -1.5707953071795862
              children [
                Shape {
                  appearance PBRAppearance {
                    baseColor 0 0 0
                    roughness 1
                    metalness 0
                  }
                  geometry Box {
                    size 0.002 0.02 0.018
                  }
                }
              ]
              name "lidar(10)"
              lookupTable [
                0 0 0
                0.255 255 0
              ]
              type "laser"
              aperture 0
              gaussianWidth 0.1
            }
            DistanceSensor {
              translation -0.074 -0.116 0.016
              rotation 0 0 1 -1.5707953071795862
              children [
                Shape {
                  appearance PBRAppearance {
                    baseColor 0 0 0
                    roughness 1
                    metalness 0
                  }
                  geometry Box {
                    size 0.002 0.02 0.018
                  }
                }
              ]
              name "lidar(11)"
              lookupTable [
                0 0 0
                0.255 255 0
              ]
              type "laser"
              aperture 0
              gaussianWidth 0.1
            }
            DistanceSensor {
              translation 0.114 0 0.005
              rotation 0.577349935856137 0.5773509358560258 -0.577349935856137 2.09439
              children [
                Shape {
                  appearance PBRAppearance {
                    baseColor 0 0 0
                    roughness 1
                    metalness 0
                  }
                  geometry Box {
                    size 0.002 0.02 0.018
                  }
                }
              ]
              name "emergencyLidar"
              lookupTable [
                0 0 0
                0.255 255 0
              ]
              type "laser"
              aperture 0
              gaussianWidth 0.1
            }
            DistanceSensor {
              translation -0.108 -0.001 0.016
              rotation 0 0 1 3.14159
              children [
                Shape {
                  appearance PBRAppearance {
                    baseColor 0 0 0
                    roughness 1
                    metalness 0
                  }
                  geometry Box {
                    size 0.002 0.02 0.018
                  }
                }
              ]
              name "lidar"
              lookupTable [
                0 0 0
                0.255 255 0
              ]
              type "laser"
              aperture 0
              gaussianWidth 0.1
            }
            DistanceSensor {
              translation 0.007 0.114 0.016
              rotation 0 0 -1 -1.5707953071795862
              children [
                Shape {
                  appearance PBRAppearance {
                    baseColor 0 0 0
                    roughness 1
                    metalness 0
                  }
                  geometry Box {
                    size 0.002 0.02 0.018
                  }
                }
              ]
              name "lidar(2)"
              lookupTable [
                0 0 0
                0.255 255 0
              ]
              type "laser"
              aperture 0
              gaussianWidth 0.1
            }
            DistanceSensor {
              translation -0.073 0.114 0.016
              rotation 0 0 -1 -1.5707953071795862
              children [
                Shape {
                  appearance PBRAppearance {
                    baseColor 0 0 0
                    roughness 1
                    metalness 0
                  }
                  geometry Box {
                    size 0.002 0.02 0.018
                  }
                }
              ]
              name "lidar(1)"
              lookupTable [
                0 0 0
                0.255 255 0
              ]
              type "laser"
              aperture 0
              gaussianWidth 0.1
            }
            DistanceSensor {
              translation 0.087 0.114 0.016
              rotation 0 0 -1 -1.5707953071795862
              children [
                Shape {
                  appearance PBRAppearance {
                    baseColor 0 0 0
                    roughness 1
                    metalness 0
                  }
                  geometry Box {
                    size 0.002 0.02 0.018
                  }
                }
              ]
              name "lidar(3)"
              lookupTable [
                0 0 0
                0.255 255 0
              ]
              type "laser"
              aperture 0
              gaussianWidth 0.1
            }
          ]
        }
        DEF LEDS_GROUP Group {
          children [
            LED {
              translation -0.12 -0.030001 0.0199988
              rotation 6.247492484361515e-07 0.707106281186034 -0.7071072811864317 3.1415853071795863
              children [
                SpotLight {
                  attenuation 0 0 1
                  beamWidth 0
                  color 0 0 0
                  cutOffAngle 0.1
                  direction 0 0 0
                  intensity 0.1
                  on FALSE
                  radius 1
                }
              ]
            }
            LED {
              translation -0.12 -0.06 0.0199988
              rotation 6.247492484361515e-07 0.707106281186034 -0.7071072811864317 3.1415853071795863
              children [
                SpotLight {
                  attenuation 0 0 1
                  beamWidth 0
                  color 0 0 0
                  cutOffAngle 0.1
                  direction 0 0 0
                  intensity 0.1
                  on FALSE
                  radius 1
                }
              ]
              name "led(1)"
            }
            LED {
              translation -0.12 -0.09 0.0199988
              rotation 6.247492484361515e-07 0.707106281186034 -0.7071072811864317 3.1415853071795863
              children [
                SpotLight {
                  attenuation 0 0 1
                  beamWidth 0
                  color 0 0 0
                  cutOffAngle 0.1
                  direction 0 0 0
                  intensity 0.1
                  on FALSE
                  radius 1
                }
              ]
              name "led(2)"
            }
            LED {
              translation -0.09 -0.125 0.02
              rotation 6.247492484361515e-07 0.707106281186034 -0.7071072811864317 3.1415853071795863
              children [
                SpotLight {
                  attenuation 0 0 1
                  beamWidth 0
                  color 0 0 0
                  cutOffAngle 0.1
                  direction 0 0 0
                  intensity 0.1
                  on FALSE
                  radius 1
                }
              ]
              name "led(3)"
            }
            LED {
              translation -0.065 -0.128 0.0200002
              rotation 6.247492484361515e-07 0.707106281186034 -0.7071072811864317 3.1415853071795863
              children [
                SpotLight {
                  attenuation 0 0 1
                  beamWidth 0
                  color 0 0 0
                  cutOffAngle 0.1
                  direction 0 0 0
                  intensity 0.1
                  on FALSE
                  radius 1
                }
              ]
              name "led(4)"
            }
            LED {
              translation -0.035 -0.128 0.0200004
              rotation 6.247492484361515e-07 0.707106281186034 -0.7071072811864317 3.1415853071795863
              children [
                SpotLight {
                  attenuation 0 0 1
                  beamWidth 0
                  color 0 0 0
                  cutOffAngle 0.1
                  direction 0 0 0
                  intensity 0.1
                  on FALSE
                  radius 1
                }
              ]
              name "led(5)"
            }
            LED {
              translation -0.005 -0.128 0.0200006
              rotation 6.247492484361515e-07 0.707106281186034 -0.7071072811864317 3.1415853071795863
              children [
                SpotLight {
                  attenuation 0 0 1
                  beamWidth 0
                  color 0 0 0
                  cutOffAngle 0.1
                  direction 0 0 0
                  intensity 0.1
                  on FALSE
                  radius 1
                }
              ]
              name "led(6)"
            }
            LED {
              translation 0.025 -0.128 0.0200008
              rotation 6.247492484361515e-07 0.707106281186034 -0.7071072811864317 3.1415853071795863
              children [
                SpotLight {
                  attenuation 0 0 1
                  beamWidth 0
                  color 0 0 0
                  cutOffAngle 0.1
                  direction 0 0 0
                  intensity 0.1
                  on FALSE
                  radius 1
                }
              ]
              name "led(7)"
            }
            LED {
              translation 0.055 -0.128 0.020001
              rotation 6.247492484361515e-07 0.707106281186034 -0.7071072811864317 3.1415853071795863
              children [
                SpotLight {
                  attenuation 0 0 1
                  beamWidth 0
                  color 0 0 0
                  cutOffAngle 0.1
                  direction 0 0 0
                  intensity 0.1
                  on FALSE
                  radius 1
                }
              ]
              name "led(8)"
            }
            LED {
              translation 0.085 -0.128 0.0200012
              rotation 6.247492484361515e-07 0.707106281186034 -0.7071072811864317 3.1415853071795863
              children [
                SpotLight {
                  attenuation 0 0 1
                  beamWidth 0
                  color 0 0 0
                  cutOffAngle 0.1
                  direction 0 0 0
                  intensity 0.1
                  on FALSE
                  radius 1
                }
              ]
              name "led(9)"
            }
            LED {
              translation 0.132 -0.108 0.0200016
              rotation 6.247492484361515e-07 0.707106281186034 -0.7071072811864317 3.1415853071795863
              children [
                SpotLight {
                  attenuation 0 0 1
                  beamWidth 0
                  color 0 0 0
                  cutOffAngle 0.1
                  direction 0 0 0
                  intensity 0.1
                  on FALSE
                  radius 1
                }
              ]
              name "led(10)"
            }
            LED {
              translation 0.132 -0.078 0.0200016
              rotation 6.247492484361515e-07 0.707106281186034 -0.7071072811864317 3.1415853071795863
              children [
                SpotLight {
                  attenuation 0 0 1
                  beamWidth 0
                  color 0 0 0
                  cutOffAngle 0.1
                  direction 0 0 0
                  intensity 0.1
                  on FALSE
                  radius 1
                }
              ]
              name "led(11)"
            }
            LED {
              translation 0.132 -0.048 0.0200016
              rotation 6.247492484361515e-07 0.707106281186034 -0.7071072811864317 3.1415853071795863
              children [
                SpotLight {
                  attenuation 0 0 1
                  beamWidth 0
                  color 0 0 0
                  cutOffAngle 0.1
                  direction 0 0 0
                  intensity 0.1
                  on FALSE
                  radius 1
                }
              ]
              name "led(12)"
            }
            LED {
              translation 0.132 -0.018 0.0200016
              rotation 6.247492484361515e-07 0.707106281186034 -0.7071072811864317 3.1415853071795863
              children [
                SpotLight {
                  attenuation 0 0 1
                  beamWidth 0
                  color 0 0 0
                  cutOffAngle 0.1
                  direction 0 0 0
                  intensity 0.1
                  on FALSE
                  radius 1
                }
              ]
              name "led(13)"
            }
            LED {
              translation 0.132 0.012 0.0200016
              rotation 6.247492484361515e-07 0.707106281186034 -0.7071072811864317 3.1415853071795863
              children [
                SpotLight {
                  attenuation 0 0 1
                  beamWidth 0
                  color 0 0 0
                  cutOffAngle 0.1
                  direction 0 0 0
                  intensity 0.1
                  on FALSE
                  radius 1
                }
              ]
              name "led(14)"
            }
            LED {
              translation 0.132 0.042 0.0200016
              rotation 6.247492484361515e-07 0.707106281186034 -0.7071072811864317 3.1415853071795863
              children [
                SpotLight {
                  attenuation 0 0 1
                  beamWidth 0
                  color 0 0 0
                  cutOffAngle 0.1
                  direction 0 0 0
                  intensity 0.1
                  on FALSE
                  radius 1
                }
              ]
              name "led(15)"
            }
            LED {
              translation 0.132 0.072 0.0200016
              rotation 6.247492484361515e-07 0.707106281186034 -0.7071072811864317 3.1415853071795863
              children [
                SpotLight {
                  attenuation 0 0 1
                  beamWidth 0
                  color 0 0 0
                  cutOffAngle 0.1
                  direction 0 0 0
                  intensity 0.1
                  on FALSE
                  radius 1
                }
              ]
              name "led(16)"
            }
            LED {
              translation 0.122 0.123 0.0200015
              rotation 6.247492484361515e-07 0.707106281186034 -0.7071072811864317 3.1415853071795863
              children [
                SpotLight {
                  attenuation 0 0 1
                  beamWidth 0
                  color 0 0 0
                  cutOffAngle 0.1
                  direction 0 0 0
                  intensity 0.1
                  on FALSE
                  radius 1
                }
              ]
              name "led(17)"
            }
            LED {
              translation 0.085 0.123 0.0200015
              rotation 6.247492484361515e-07 0.707106281186034 -0.7071072811864317 3.1415853071795863
              children [
                SpotLight {
                  attenuation 0 0 1
                  beamWidth 0
                  color 0 0 0
                  cutOffAngle 0.1
                  direction 0 0 0
                  intensity 0.1
                  on FALSE
                  radius 1
                }
              ]
              name "led(18)"
            }
            LED {
              translation 0.055 0.123 0.0200015
              rotation 6.247492484361515e-07 0.707106281186034 -0.7071072811864317 3.1415853071795863
              children [
                SpotLight {
                  attenuation 0 0 1
                  beamWidth 0
                  color 0 0 0
                  cutOffAngle 0.1
                  direction 0 0 0
                  intensity 0.1
                  on FALSE
                  radius 1
                }
              ]
              name "led(19)"
            }
            LED {
              translation 0.025 0.123 0.0200015
              rotation 6.247492484361515e-07 0.707106281186034 -0.7071072811864317 3.1415853071795863
              children [
                SpotLight {
                  attenuation 0 0 1
                  beamWidth 0
                  color 0 0 0
                  cutOffAngle 0.1
                  direction 0 0 0
                  intensity 0.1
                  on FALSE
                  radius 1
                }
              ]
              name "led(20)"
            }
            LED {
              translation -0.005 0.123 0.0200015
              rotation 6.247492484361515e-07 0.707106281186034 -0.7071072811864317 3.1415853071795863
              children [
                SpotLight {
                  attenuation 0 0 1
                  beamWidth 0
                  color 0 0 0
                  cutOffAngle 0.1
                  direction 0 0 0
                  intensity 0.1
                  on FALSE
                  radius 1
                }
              ]
              name "led(21)"
            }
            LED {
              translation -0.035 0.123 0.0200015
              rotation 6.247492484361515e-07 0.707106281186034 -0.7071072811864317 3.1415853071795863
              children [
                SpotLight {
                  attenuation 0 0 1
                  beamWidth 0
                  color 0 0 0
                  cutOffAngle 0.1
                  direction 0 0 0
                  intensity 0.1
                  on FALSE
                  radius 1
                }
              ]
              name "led(22)"
            }
            LED {
              translation -0.065 0.123 0.0200015
              rotation 6.247492484361515e-07 0.707106281186034 -0.7071072811864317 3.1415853071795863
              children [
                SpotLight {
                  attenuation 0 0 1
                  beamWidth 0
                  color 0 0 0
                  cutOffAngle 0.1
                  direction 0 0 0
                  intensity 0.1
                  on FALSE
                  radius 1
                }
              ]
              name "led(23)"
            }
            LED {
              translation -0.11 0.103 0.0200012
              rotation 6.247492484361515e-07 0.707106281186034 -0.7071072811864317 3.1415853071795863
              children [
                SpotLight {
                  attenuation 0 0 1
                  beamWidth 0
                  color 0 0 0
                  cutOffAngle 0.1
                  direction 0 0 0
                  intensity 0.1
                  on FALSE
                  radius 1
                }
              ]
              name "led(24)"
            }
            LED {
              translation -0.12 0.062 0.0200011
              rotation 6.247492484361515e-07 0.707106281186034 -0.7071072811864317 3.1415853071795863
              children [
                SpotLight {
                  attenuation 0 0 1
                  beamWidth 0
                  color 0 0 0
                  cutOffAngle 0.1
                  direction 0 0 0
                  intensity 0.1
                  on FALSE
                  radius 1
                }
              ]
              name "led(25)"
            }
          ]
        }
        DEF wheel_back BallJoint {
          jointParameters BallJointParameters {
            position -0.007694442785123247
            anchor -0.09 0 -0.005
          }
          jointParameters2 JointParameters {
            position -0.010956747480667193
          }
          jointParameters3 JointParameters {
            position 114.91687487858445
            axis 0 1 0
          }
          endPoint Solid {
            translation -0.0899950455670005 -1.8923534288064862e-08 -0.004991592050994658
            rotation 0.0013343982823836832 0.999967870197995 -0.007904299647005288 1.8195930974137735
            children [
              DEF UNIVERSAL_WHEEL Shape {
                appearance PBRAppearance {
                  baseColor 0 0 0
                  roughness 1
                  metalness 0
                }
                geometry Sphere {
                  radius 0.01
                }
              }
            ]
            name "solid(3)"
            boundingObject USE UNIVERSAL_WHEEL
            physics Physics {
            }
            linearVelocity -2.4410978056502814e-08 -5.067332135140882e-11 -8.44957946272876e-06
            angularVelocity -2.1678238740352324e-09 -4.420013216503929e-06 2.4287864811221377e-11
          }
        }
        DEF wheel_front BallJoint {
          jointParameters BallJointParameters {
            position -0.008189244559462619
            anchor 0.1 0 -0.005
          }
          jointParameters2 JointParameters {
            position -0.05984628103814048
          }
          jointParameters3 JointParameters {
            position 116.8908653136687
            axis 0 1 0
          }
          endPoint Solid {
            translation 0.10000511099949588 5.186764596206567e-08 -0.00499131019092443
            rotation 0.015097780898728683 0.99961229185478 -0.023394935023808083 -2.489831792440012
            children [
              DEF UNIVERSAL_WHEEL Shape {
                appearance PBRAppearance {
                  baseColor 0 0 0
                  roughness 1
                  metalness 0
                }
                geometry Sphere {
                  radius 0.01
                }
              }
            ]
            name "solid(2)"
            boundingObject USE UNIVERSAL_WHEEL
            physics Physics {
            }
            linearVelocity -2.465594233058706e-08 -4.0657840519961847e-10 -8.098754934773316e-06
            angularVelocity 6.231140324486856e-08 -4.566002451338648e-06 2.728941576835572e-11
          }
        }
        Camera {
          translation 0.0607 -0.001 0.1663
          rotation 0 1 0 -0.620795307179586
          children [
            Pose {
              rotation 0 1 0 1.5708
              children [
                Shape {
                  appearance PBRAppearance {
                    roughness 0.1
                    metalness 0.9
                  }
                  geometry Cylinder {
                    height 0.01
                    radius 0.0073
                  }
                }
              ]
            }
          ]
          fieldOfView 2.04
          width 3296
          height 2512
          far 1000
          lens Lens {
          }
        }
        Solid {
          translation 0.1036 -0.001 0.1125
          rotation 0 1 0 0.95
          children [
            Shape {
              appearance PBRAppearance {
                roughness 0.2
                metalness 0.9
              }
              geometry Box {
                size 0.115 0.166 0.002
              }
              castShadows FALSE
              isPickable FALSE
            }
            Display {
            }
          ]
          name "Screen"
        }
        Speaker {
          translation 0 0 0.21
        }
        DEF wheel_right HingeJoint {
          jointParameters HingeJointParameters {
            position 128.78734066243175
            axis 0 1 0
            anchor -9.092519999999895e-07 -0.07999998763551178 0.010019798720924688
          }
          device [
            RotationalMotor {
              name "motor_right"
            }
          ]
          endPoint Solid {
            translation -9.126964387066396e-07 -0.08000001165951812 0.010019990504118023
            rotation 0.006345811994840364 0.7070908019939836 -0.7070942853719235 3.1288871678926715
            children [
              DEF WHEEL Shape {
                appearance PBRAppearance {
                  baseColor 0 0 0
                  roughness 1
                  metalness 0
                }
                geometry Cylinder {
                  height 0.01
                  radius 0.025
                }
              }
            ]
            boundingObject USE WHEEL
            physics DEF WHEEL_PhYSICS Physics {
            }
            linearVelocity -2.469546734733458e-08 -4.228630873174261e-10 -5.670809263895196e-07
            angularVelocity 1.5468988157062256e-08 -5.762808087506401e-07 -1.5547698973001755e-09
          }
        }
        DEF wheel_left HingeJoint {
          jointParameters HingeJointParameters {
            position 128.78734543649568
            axis 0 1 0
            anchor 7.207369999999995e-07 0.0799999876424674 0.010015098711698348
          }
          device [
            RotationalMotor {
              name "motor_left"
            }
          ]
          endPoint Solid {
            translation 7.173203984072904e-07 0.0800000114674744 0.010015288995543326
            rotation 0.0063439823767493285 0.7070916252391651 -0.7070934785473837 3.1288902600472723
            children [
              USE WHEEL
            ]
            name "solid(1)"
            boundingObject USE WHEEL
            physics USE WHEEL_PhYSICS
            linearVelocity -2.452054768589894e-08 -4.2283282179960574e-10 -5.658707999815478e-07
            angularVelocity 1.5469424430518406e-08 -5.762720758425855e-07 -1.5547694941245974e-09
          }
        }
        DEF Carcasa Shape {
          appearance PBRAppearance {
            roughness 1
            metalness 0
          }
          geometry Mesh {
            url [
              "../resources/meshes/EBO_Carcasa.stl"
            ]
          }
        }
        DEF Base Shape {
          appearance PBRAppearance {
            roughness 1
            metalness 0
          }
          geometry Mesh {
            url [
              "../resources/meshes/EBO_Base.stl"
            ]
          }
        }
      ]
    }
  ]
  name "EBO"
  model "EBOv2"
  boundingObject Pose {
    translation 0 0 0.01
    children [
      Mesh {
        url [
          "../resources/meshes/EBO_Collision.stl"
        ]
      }
    ]
  }
  physics Physics {
    density -1
    mass 2.4
  }
  controller "<extern>"
  supervisor TRUE
  linearVelocity -6.983784100766718e-08 -1.5420329262574936e-09 -1.676474691412486e-05
  angularVelocity 1.5474906524489856e-08 -5.757666523060895e-07 -1.5547502960865005e-09
}
